Workbook

Sheet Taxi_Data1
A1: Ride_ID | B1: START_DATE | C1: END_DATE | D1: CATEGORY | E1: START | F1: STOP | G1: MILES | H1: PURPOSE | I1: Travel_Time | J1: Start_Hour | K1: WeekDay | L1: To_Fro_Rides
A2: RID_075 | B2: 42370.883 | C2: 42370.887 | D2: Business | E2: Fort Pierce | F2: Fort Pierce | G2: 5.1 | H2: Meal/Entertain | I2: =HOUR(C2-B2)&" hrs " & MINUTE(C2-B2) & " mins" -> 0 hrs 6 mins | J2: =HOUR(B2) -> 21 | K2: =TEXT(B2,"dddd") -> Friday | L2: =IF(E2=F2,"To and Fro", "One Way") -> To and Fro
A3: RID_076 | B3: 42401.059 | C3: 42401.067 | D3: Business | E3: Fort Pierce | F3: Fort Pierce | G3: 5 | I3: =HOUR(C3-B3)&" hrs " & MINUTE(C3-B3) & " mins" -> 0 hrs 12 mins | J3: =HOUR(B3) -> 1 | K3: =TEXT(B3,"dddd") -> Monday | L3: =IF(E3=F3,"To and Fro", "One Way") -> To and Fro
A4: RID_077 | B4: 42401.851 | C4: 42401.86 | D4: Business | E4: Fort Pierce | F4: Fort Pierce | G4: 4.8 | H4: Errand/Supplies | I4: =HOUR(C4-B4)&" hrs " & MINUTE(C4-B4) & " mins" -> 0 hrs 13 mins | J4: =HOUR(B4) -> 20 | K4: =TEXT(B4,"dddd") -> Monday | L4: =IF(E4=F4,"To and Fro", "One Way") -> To and Fro
A5: RID_078 | B5: 42491.73 | C5: 42491.74 | D5: Business | E5: Fort Pierce | F5: Fort Pierce | G5: 4.7 | H5: Meeting | I5: =HOUR(C5-B5)&" hrs " & MINUTE(C5-B5) & " mins" -> 0 hrs 14 mins | J5: =HOUR(B5) -> 17 | K5: =TEXT(B5,"dddd") -> Sunday | L5: =IF(E5=F5,"To and Fro", "One Way") -> To and Fro
A6: RID_079 | B6: 42522.613 | C6: 42522.659 | D6: Business | E6: Fort Pierce | F6: West Palm Beach | G6: 63.7 | H6: Customer Visit | I6: =HOUR(C6-B6)&" hrs " & MINUTE(C6-B6) & " mins" -> 1 hrs 7 mins | J6: =HOUR(B6) -> 14 | K6: =TEXT(B6,"dddd") -> Wednesday | L6: =IF(E6=F6,"To and Fro", "One Way") -> One Way
A7: RID_080 | B7: 42522.719 | C7: 42522.722 | D7: Business | E7: West Palm Beach | F7: West Palm Beach | G7: 4.3 | H7: Meal/Entertain | I7: =HOUR(C7-B7)&" hrs " & MINUTE(C7-B7) & " mins" -> 0 hrs 4 mins | J7: =HOUR(B7) -> 17 | K7: =TEXT(B7,"dddd") -> Wednesday | L7: =IF(E7=F7,"To and Fro", "One Way") -> To and Fro
A8: RID_081 | B8: 42522.729 | C8: 42522.733 | D8: Business | E8: West Palm Beach | F8: Palm Beach | G8: 7.1 | H8: Meeting | I8: =HOUR(C8-B8)&" hrs " & MINUTE(C8-B8) & " mins" -> 0 hrs 5 mins | J8: =HOUR(B8) -> 17 | K8: =TEXT(B8,"dddd") -> Wednesday | L8: =IF(E8=F8,"To and Fro", "One Way") -> One Way
A9: RID_082 | B9: 42552.56 | C9: 42552.565 | D9: Business | E9: Cary | F9: Cary | G9: 0.8 | H9: Meeting | I9: =HOUR(C9-B9)&" hrs " & MINUTE(C9-B9) & " mins" -> 0 hrs 6 mins | J9: =HOUR(B9) -> 13 | K9: =TEXT(B9,"dddd") -> Friday | L9: =IF(E9=F9,"To and Fro", "One Way") -> To and Fro
A10: RID_083 | B10: 42644.337 | C10: 42644.351 | D10: Business | E10: Cary | F10: Morrisville | G10: 8.3 | H10: Meeting | I10: =HOUR(C10-B10)&" hrs " & MINUTE(C10-B10) & " mins" -> 0 hrs 20 mins | J10: =HOUR(B10) -> 8 | K10: =TEXT(B10,"dddd") -> Saturday | L10: =IF(E10=F10,"To and Fro", "One Way") -> One Way
A11: RID_084 | B11: 42644.512 | C11: 42644.531 | D11: Business | E11: Jamaica | F11: New York | G11: 16.5 | H11: Customer Visit | I11: =HOUR(C11-B11)&" hrs " & MINUTE(C11-B11) & " mins" -> 0 hrs 27 mins | J11: =HOUR(B11) -> 12 | K11: =TEXT(B11,"dddd") -> Saturday | L11: =IF(E11=F11,"To and Fro", "One Way") -> One Way
A12: RID_085 | B12: 42644.631 | C12: 42644.66 | D12: Business | E12: New York | F12: Queens | G12: 10.8 | H12: Meeting | I12: =HOUR(C12-B12)&" hrs " & MINUTE(C12-B12) & " mins" -> 0 hrs 43 mins | J12: =HOUR(B12) -> 15 | K12: =TEXT(B12,"dddd") -> Saturday | L12: =IF(E12=F12,"To and Fro", "One Way") -> One Way
A13: RID_086 | B13: 42644.762 | C13: 42644.787 | D13: Business | E13: Elmhurst | F13: New York | G13: 7.5 | H13: Meeting | I13: =HOUR(C13-B13)&" hrs " & MINUTE(C13-B13) & " mins" -> 0 hrs 35 mins | J13: =HOUR(B13) -> 18 | K13: =TEXT(B13,"dddd") -> Saturday | L13: =IF(E13=F13,"To and Fro", "One Way") -> One Way
A14: RID_087 | B14: 42644.8 | C14: 42644.814 | D14: Business | E14: Midtown | F14: East Harlem | G14: 6.2 | H14: Meeting | I14: =HOUR(C14-B14)&" hrs " & MINUTE(C14-B14) & " mins" -> 0 hrs 20 mins | J14: =HOUR(B14) -> 19 | K14: =TEXT(B14,"dddd") -> Saturday | L14: =IF(E14=F14,"To and Fro", "One Way") -> One Way
A15: RID_088 | B15: 42675.372 | C15: 42675.39 | D15: Business | E15: East Harlem | F15: NoMad | G15: 6.4 | H15: Temporary Site | I15: =HOUR(C15-B15)&" hrs " & MINUTE(C15-B15) & " mins" -> 0 hrs 26 mins | J15: =HOUR(B15) -> 8 | K15: =TEXT(B15,"dddd") -> Tuesday | L15: =IF(E15=F15,"To and Fro", "One Way") -> One Way
... A48: RID_121 | B48: 42584.583 | C48: 42584.59 | D48: Business | E48: Edgehill Farms | F48: Whitebridge | G48: 2.7 | H48: Meal/Entertain | I48: =HOUR(C48-B48)&" hrs " & MINUTE(C48-B48) & " mins" -> 0 hrs 10 mins | J48: =HOUR(B48) -> 14 | K48: =TEXT(B48,"dddd") -> Tuesday | L48: =IF(E48=F48,"To and Fro", "One Way") -> One Way
A49: RID_122 | B49: 42615.454 | C49: 42615.463 | D49: Personal | E49: Whitebridge | F49: Northwoods | G49: 5.3 | I49: =HOUR(C49-B49)&" hrs " & MINUTE(C49-B49) & " mins" -> 0 hrs 13 mins | J49: =HOUR(B49) -> 10 | K49: =TEXT(B49,"dddd") -> Friday | L49: =IF(E49=F49,"To and Fro", "One Way") -> One Way
A50: RID_123 | B50: 42615.488 | C50: 42615.493 | D50: Personal | E50: Northwoods | F50: Tanglewood | G50: 3 | I50: =HOUR(C50-B50)&" hrs " & MINUTE(C50-B50) & " mins" -> 0 hrs 7 mins | J50: =HOUR(B50) -> 11 | K50: =TEXT(B50,"dddd") -> Friday | L50: =IF(E50=F50,"To and Fro", "One Way") -> One Way
A51: RID_124 | B51: 42615.567 | C51: 42615.578 | D51: Personal | E51: Tanglewood | F51: Preston | G51: 5.1 | I51: =HOUR(C51-B51)&" hrs " & MINUTE(C51-B51) & " mins" -> 0 hrs 16 mins | J51: =HOUR(B51) -> 13 | K51: =TEXT(B51,"dddd") -> Friday | L51: =IF(E51=F51,"To and Fro", "One Way") -> One Way
A52: RID_125 | B52: 42615.582 | C52: 42615.585 | D52: Personal | E52: Preston | F52: Whitebridge | G52: 1.5 | I52: =HOUR(C52-B52)&" hrs " & MINUTE(C52-B52) & " mins" -> 0 hrs 4 mins | J52: =HOUR(B52) -> 13 | K52: =TEXT(B52,"dddd") -> Friday | L52: =IF(E52=F52,"To and Fro", "One Way") -> One Way
A53: RID_126 | B53: 42615.788 | C53: 42615.799 | D53: Business | E53: Cary | F53: Morrisville | G53: 6.1 | I53: =HOUR(C53-B53)&" hrs " & MINUTE(C53-B53) & " mins" -> 0 hrs 16 mins | J53: =HOUR(B53) -> 18 | K53: =TEXT(B53,"dddd") -> Friday | L53: =IF(E53=F53,"To and Fro", "One Way") -> One Way
A54: RID_127 | B54: 42615.85 | C54: 42615.861 | D54: Business | E54: Morrisville | F54: Cary | G54: 6.1 | H54: Meal/Entertain | I54: =HOUR(C54-B54)&" hrs " & MINUTE(C54-B54) & " mins" -> 0 hrs 16 mins | J54: =HOUR(B54) -> 20 | K54: =TEXT(B54,"dddd") -> Friday | L54: =IF(E54=F54,"To and Fro", "One Way") -> One Way
A55: RID_128 | B55: 42676.686 | C55: 42676.715 | D55: Business | E55: Cary | F55: Raleigh | G55: 17.3 | H55: Meal/Entertain | I55: =HOUR(C55-B55)&" hrs " & MINUTE(C55-B55) & " mins" -> 0 hrs 42 mins | J55: =HOUR(B55) -> 16 | K55: =TEXT(B55,"dddd") -> Wednesday | L55: =IF(E55=F55,"To and Fro", "One Way") -> One Way
A56: RID_129 | B56: 42676.742 | C56: 42676.757 | D56: Business | E56: Eastgate | F56: Walnut Terrace | G56: 5.7 | H56: Meal/Entertain | I56: =HOUR(C56-B56)&" hrs " & MINUTE(C56-B56) & " mins" -> 0 hrs 21 mins | J56: =HOUR(B56) -> 17 | K56: =TEXT(B56,"dddd") -> Wednesday | L56: =IF(E56=F56,"To and Fro", "One Way") -> One Way
A57: RID_130 | B57: 42676.767 | C57: 42676.782 | D57: Business | E57: Raleigh | F57: Morrisville | G57: 13.5 | H57: Temporary Site | I57: =HOUR(C57-B57)&" hrs " & MINUTE(C57-B57) & " mins" -> 0 hrs 22 mins | J57: =HOUR(B57) -> 18 | K57: =TEXT(B57,"dddd") -> Wednesday | L57: =IF(E57=F57,"To and Fro", "One Way") -> One Way
A58: RID_131 | B58: 42676.858 | C58: 42676.869 | D58: Business | E58: Morrisville | F58: Cary | G58: 6.1 | H58: Temporary Site | I58: =HOUR(C58-B58)&" hrs " & MINUTE(C58-B58) & " mins" -> 0 hrs 15 mins | J58: =HOUR(B58) -> 20 | K58: =TEXT(B58,"dddd") -> Wednesday | L58: =IF(E58=F58,"To and Fro", "One Way") -> One Way
A59: RID_132 | B59: 42706.348 | C59: 42706.363 | D59: Business | E59: Cary | F59: Durham | G59: 8.5 | H59: Temporary Site | I59: =HOUR(C59-B59)&" hrs " & MINUTE(C59-B59) & " mins" -> 0 hrs 21 mins | J59: =HOUR(B59) -> 8 | K59: =TEXT(B59,"dddd") -> Friday | L59: =IF(E59=F59,"To and Fro", "One Way") -> One Way
A60: RID_133 | B60: 42706.448 | C60: 42706.453 | D60: Business | E60: Durham | F60: Morrisville | G60: 2.6 | H60: Temporary Site | I60: =HOUR(C60-B60)&" hrs " & MINUTE(C60-B60) & " mins" -> 0 hrs 7 mins | J60: =HOUR(B60) -> 10 | K60: =TEXT(B60,"dddd") -> Friday | L60: =IF(E60=F60,"To and Fro", "One Way") -> One Way
A61: RID_134 | B61: 42706.468 | C61: 42706.483 | D61: Business | E61: Morrisville | F61: Raleigh | G61: 17 | H61: Customer Visit | I61: =HOUR(C61-B61)&" hrs " & MINUTE(C61-B61) & " mins" -> 0 hrs 21 mins | J61: =HOUR(B61) -> 11 | K61: =TEXT(B61,"dddd") -> Friday | L61: =IF(E61=F61,"To and Fro", "One Way") -> One Way
A62: RID_135 | B62: 42706.543 | C62: 42706.567 | D62: Business | E62: Raleigh | F62: Cary | G62: 18 | H62: Meeting | I62: =HOUR(C62-B62)&" hrs " & MINUTE(C62-B62) & " mins" -> 0 hrs 34 mins | J62: =HOUR(B62) -> 13 | K62: =TEXT(B62,"dddd") -> Friday | L62: =IF(E62=F62,"To and Fro", "One Way") -> One Way
A63: RID_136 | B63: 42706.617 | C63: 42706.629 | D63: Business | E63: Cary | F63: Morrisville | G63: 8.4 | H63: Meeting | I63: =HOUR(C63-B63)&" hrs " & MINUTE(C63-B63) & " mins" -> 0 hrs 17 mins | J63: =HOUR(B63) -> 14 | K63: =TEXT(B63,"dddd") -> Friday | L63: =IF(E63=F63,"To and Fro", "One Way") -> One Way
A64: RID_137 | B64: 42706.648 | C64: 42706.671 | D64: Business | E64: Morrisville | F64: Cary | G64: 11.5 | H64: Customer Visit | I64: =HOUR(C64-B64)&" hrs " & MINUTE(C64-B64) & " mins" -> 0 hrs 33 mins | J64: =HOUR(B64) -> 15 | K64: =TEXT(B64,"dddd") -> Friday | L64: =IF(E64=F64,"To and Fro", "One Way") -> One Way
A65: RID_138 | B65: 42372.783 | C65: 42372.799 | D65: Business | E65: Whitebridge | F65: Wayne Ridge | G65: 8 | H65: Meal/Entertain | I65: =HOUR(C65-B65)&" hrs " & MINUTE(C65-B65) & " mins" -> 0 hrs 23 mins | J65: =HOUR(B65) -> 18 | K65: =TEXT(B65,"dddd") -> Sunday | L65: =IF(E65=F65,"To and Fro", "One Way") -> One Way
A66: RID_139 | B66: 42372.894 | C66: 42372.906 | D66: Business | E66: Wayne Ridge | F66: Whitebridge | G66: 8 | H66: Meeting | I66: =HOUR(C66-B66)&" hrs " & MINUTE(C66-B66) & " mins" -> 0 hrs 18 mins | J66: =HOUR(B66) -> 21 | K66: =TEXT(B66,"dddd") -> Sunday | L66: =IF(E66=F66,"To and Fro", "One Way") -> One Way
A67: RID_140 | B67: 42432.406 | C67: 42432.411 | D67: Personal | E67: Whitebridge | F67: Westpark Place | G67: 2.2 | I67: =HOUR(C67-B67)&" hrs " & MINUTE(C67-B67) & " mins" -> 0 hrs 7 mins | J67: =HOUR(B67) -> 9 | K67: =TEXT(B67,"dddd") -> Thursday | L67: =IF(E67=F67,"To and Fro", "One Way") -> One Way
A68: RID_141 | B68: 42432.461 | C68: 42432.465 | D68: Business | E68: Westpark Place | F68: Whitebridge | G68: 2.3 | H68: Errand/Supplies | I68: =HOUR(C68-B68)&" hrs " & MINUTE(C68-B68) & " mins" -> 0 hrs 6 mins | J68: =HOUR(B68) -> 11 | K68: =TEXT(B68,"dddd") -> Thursday | L68: =IF(E68=F68,"To and Fro", "One Way") -> One Way
A69: RID_142 | B69: 42432.614 | C69: 42432.624 | D69: Business | E69: Whitebridge | F69: Northwoods | G69: 5.2 | H69: Meal/Entertain | I69: =HOUR(C69-B69)&" hrs " & MINUTE(C69-B69) & " mins" -> 0 hrs 14 mins | J69: =HOUR(B69) -> 14 | K69: =TEXT(B69,"dddd") -> Thursday | L69: =IF(E69=F69,"To and Fro", "One Way") -> One Way
A70: RID_143 | B70: 42432.644 | C70: 42432.658 | D70: Business | E70: Cary | F70: Raleigh | G70: 7.6 | H70: Customer Visit | I70: =HOUR(C70-B70)&" hrs " & MINUTE(C70-B70) & " mins" -> 0 hrs 21 mins | J70: =HOUR(B70) -> 15 | K70: =TEXT(B70,"dddd") -> Thursday | L70: =IF(E70=F70,"To and Fro", "One Way") -> One Way
A71: RID_144 | B71: 42432.668 | C71: 42432.696 | D71: Business | E71: Raleigh | F71: Cary | G71: 17.3 | H71: Meeting | I71: =HOUR(C71-B71)&" hrs " & MINUTE(C71-B71) & " mins" -> 0 hrs 40 mins | J71: =HOUR(B71) -> 16 | K71: =TEXT(B71,"dddd") -> Thursday | L71: =IF(E71=F71,"To and Fro", "One Way") -> One Way
A72: RID_145 | B72: 42463.324 | C72: 42463.338 | D72: Business | E72: Cary | F72: Durham | G72: 9.9 | H72: Meeting | I72: =HOUR(C72-B72)&" hrs " & MINUTE(C72-B72) & " mins" -> 0 hrs 19 mins | J72: =HOUR(B72) -> 7 | K72: =TEXT(B72,"dddd") -> Sunday | L72: =IF(E72=F72,"To and Fro", "One Way") -> One Way
...

Sheet Taxi_Data2
A1: Ride_ID | B1: Fare | C1: Driver
A2: RID_075 | B2: 65 | C2: Nicholas
A3: RID_076 | B3: 62 | C3: Alex
A4: RID_077 | B4: 63 | C4: David
A5: RID_078 | B5: 60 | C5: Shawn
A6: RID_079 | B6: 500 | C6: Jason
A7: RID_080 | B7: 60 | C7: Mathew
A8: RID_081 | B8: 85 | C8: Jason
A9: RID_082 | B9: 10 | C9: Javier
A10: RID_083 | B10: 92 | C10: David
A11: RID_084 | B11: 175 | C11: Ian
A12: RID_085 | B12: 110 | C12: William
A13: RID_086 | B13: 92 | C13: Carol
... A106: RID_179 | B106: 20 | C106: Lamine

Sheet Assignment_Questions
B2: Use Sheets Taxi_Data1 and Taxi_Data2
B4: Q1) Compute Travel Time for each ride like "1 hrs 20 mins"
B5: Q2) Find Overall Avg Distance, Avg Fare travelled
B6: Q3) Find top 5 Peak hours at which ride was started. Represent it on bar chart. Display data labels
B7: Q4) For the given Ride_IDs, populate Start_Date, End_Date,Driver_Fare, Distance and Travel_Time. Use Vlookup. Handle Error(Display None, if Ride_Id is not present
B9: Ride_ID | C9: Start_Date | D9: End_Date | E9: Driver | F9: Fare | G9: Distance | H9: Travel_Time
B10: RID_076 | C10: =IFERROR(VLOOKUP($B10,Taxi_Data1!$A$2:$H$106,COLUMNS($A$2:B$2),0),"None") -> 42401.059 | D10: =IFERROR(VLOOKUP($B10,Taxi_Data1!$A$2:$H$106,COLUMNS($A$2:C$2),0),"None") -> 42401.067 | E10: =IFERROR(VLOOKUP($B10,Taxi_Data2!$A$2:$C$106,MATCH($E$9,Taxi_Data2!$A$1:$C$1,0),0),"None") -> Alex | F10: =IFERROR(VLOOKUP($B10,Taxi_Data2!$A$2:$C$106,MATCH($F$9,Taxi_Data2!$A$1:$C$1,0),0),"None") -> 62 | G10: =IFERROR(VLOOKUP($B10,Taxi_Data1!$A$2:$H$106,7,0),"None") -> 5 | H10: =IFERROR(VLOOKUP($B10,Taxi_Data1!$A$2:$J$106,9,0),"None") -> 0 hrs 12 mins
B11: RID_079 | C11: =IFERROR(VLOOKUP($B11,Taxi_Data1!$A$2:$H$106,COLUMNS($A$2:B$2),0),"None") -> 42522.613 | D11: =IFERROR(VLOOKUP($B11,Taxi_Data1!$A$2:$H$106,COLUMNS($A$2:C$2),0),"None") -> 42522.659 | E11: =IFERROR(VLOOKUP($B11,Taxi_Data2!$A$2:$C$106,MATCH($E$9,Taxi_Data2!$A$1:$C$1,0),0),"None") -> Jason | F11: =IFERROR(VLOOKUP($B11,Taxi_Data2!$A$2:$C$106,MATCH($F$9,Taxi_Data2!$A$1:$C$1,0),0),"None") -> 500 | G11: =IFERROR(VLOOKUP($B11,Taxi_Data1!$A$2:$H$106,7,0),"None") -> 63.7 | H11: =IFERROR(VLOOKUP($B11,Taxi_Data1!$A$2:$J$106,9,0),"None") -> 1 hrs 7 mins
B12: RID_112 | C12: =IFERROR(VLOOKUP($B12,Taxi_Data1!$A$2:$H$106,COLUMNS($A$2:B$2),0),"None") -> 42492.557 | D12: =IFERROR(VLOOKUP($B12,Taxi_Data1!$A$2:$H$106,COLUMNS($A$2:C$2),0),"None") -> 42492.57 | E12: =IFERROR(VLOOKUP($B12,Taxi_Data2!$A$2:$C$106,MATCH($E$9,Taxi_Data2!$A$1:$C$1,0),0),"None") -> Martin | F12: =IFERROR(VLOOKUP($B12,Taxi_Data2!$A$2:$C$106,MATCH($F$9,Taxi_Data2!$A$1:$C$1,0),0),"None") -> 125 | G12: =IFERROR(VLOOKUP($B12,Taxi_Data1!$A$2:$H$106,7,0),"None") -> 10.4 | H12: =IFERROR(VLOOKUP($B12,Taxi_Data1!$A$2:$J$106,9,0),"None") -> 0 hrs 19 mins
B13: RID_184 | C13: =IFERROR(VLOOKUP($B13,Taxi_Data1!$A$2:$H$106,COLUMNS($A$2:B$2),0),"None") -> None | D13: =IFERROR(VLOOKUP($B13,Taxi_Data1!$A$2:$H$106,COLUMNS($A$2:C$2),0),"None") -> None | E13: =IFERROR(VLOOKUP($B13,Taxi_Data2!$A$2:$C$106,MATCH($E$9,Taxi_Data2!$A$1:$C$1,0),0),"None") -> None | F13: =IFERROR(VLOOKUP($B13,Taxi_Data2!$A$2:$C$106,MATCH($F$9,Taxi_Data2!$A$1:$C$1,0),0),"None") -> None | G13: =IFERROR(VLOOKUP($B13,Taxi_Data1!$A$2:$H$106,7,0),"None") -> None | H13: =IFERROR(VLOOKUP($B13,Taxi_Data1!$A$2:$J$106,9,0),"None") -> None
B14: RID_141 | C14: =IFERROR(VLOOKUP($B14,Taxi_Data1!$A$2:$H$106,COLUMNS($A$2:B$2),0),"None") -> 42432.461 | D14: =IFERROR(VLOOKUP($B14,Taxi_Data1!$A$2:$H$106,COLUMNS($A$2:C$2),0),"None") -> 42432.465 | E14: =IFERROR(VLOOKUP($B14,Taxi_Data2!$A$2:$C$106,MATCH($E$9,Taxi_Data2!$A$1:$C$1,0),0),"None") -> Eduard | F14: =IFERROR(VLOOKUP($B14,Taxi_Data2!$A$2:$C$106,MATCH($F$9,Taxi_Data2!$A$1:$C$1,0),0),"None") -> 18 | G14: =IFERROR(VLOOKUP($B14,Taxi_Data1!$A$2:$H$106,7,0),"None") -> 2.3 | H14: =IFERROR(VLOOKUP($B14,Taxi_Data1!$A$2:$J$106,9,0),"None") -> 0 hrs 6 mins
B15: RID_135 | C15: =IFERROR(VLOOKUP($B15,Taxi_Data1!$A$2:$H$106,COLUMNS($A$2:B$2),0),"None") -> 42706.543 | D15: =IFERROR(VLOOKUP($B15,Taxi_Data1!$A$2:$H$106,COLUMNS($A$2:C$2),0),"None") -> 42706.567 | E15: =IFERROR(VLOOKUP($B15,Taxi_Data2!$A$2:$C$106,MATCH($E$9,Taxi_Data2!$A$1:$C$1,0),0),"None") -> Jason | F15: =IFERROR(VLOOKUP($B15,Taxi_Data2!$A$2:$C$106,MATCH($F$9,Taxi_Data2!$A$1:$C$1,0),0),"None") -> 188 | G15: =IFERROR(VLOOKUP($B15,Taxi_Data1!$A$2:$H$106,7,0),"None") -> 18 | H15: =IFERROR(VLOOKUP($B15,Taxi_Data1!$A$2:$J$106,9,0),"None") -> 0 hrs 34 mins
B16: RID_153 | C16: =IFERROR(VLOOKUP($B16,Taxi_Data1!$A$2:$H$106,COLUMNS($A$2:B$2),0),"None") -> 42463.793 | D16: =IFERROR(VLOOKUP($B16,Taxi_Data1!$A$2:$H$106,COLUMNS($A$2:C$2),0),"None") -> 42463.797 | E16: =IFERROR(VLOOKUP($B16,Taxi_Data2!$A$2:$C$106,MATCH($E$9,Taxi_Data2!$A$1:$C$1,0),0),"None") -> Shawn | F16: =IFERROR(VLOOKUP($B16,Taxi_Data2!$A$2:$C$106,MATCH($F$9,Taxi_Data2!$A$1:$C$1,0),0),"None") -> 16 | G16: =IFERROR(VLOOKUP($B16,Taxi_Data1!$A$2:$H$106,7,0),"None") -> 1.9 | H16: =IFERROR(VLOOKUP($B16,Taxi_Data1!$A$2:$J$106,9,0),"None") -> 0 hrs 6 mins
B17: RID_159 | C17: =IFERROR(VLOOKUP($B17,Taxi_Data1!$A$2:$H$106,COLUMNS($A$2:B$2),0),"None") -> 42493.703 | D17: =IFERROR(VLOOKUP($B17,Taxi_Data1!$A$2:$H$106,COLUMNS($A$2:C$2),0),"None") -> 42493.717 | E17: =IFERROR(VLOOKUP($B17,Taxi_Data2!$A$2:$C$106,MATCH($E$9,Taxi_Data2!$A$1:$C$1,0),0),"None") -> Vincent | F17: =IFERROR(VLOOKUP($B17,Taxi_Data2!$A$2:$C$106,MATCH($F$9,Taxi_Data2!$A$1:$C$1,0),0),"None") -> 87 | G17: =IFERROR(VLOOKUP($B17,Taxi_Data1!$A$2:$H$106,7,0),"None") -> 7.8 | H17: =IFERROR(VLOOKUP($B17,Taxi_Data1!$A$2:$J$106,9,0),"None") -> 0 hrs 21 mins
B19: Q6) Find the Count of each Start and End Locations
B21: Start_Location | C21: Count | D21: End_Location | E21: Count
B22: Fort Pierce | C22: =COUNTIF(Taxi_Data1!E2:E106,B22) -> 5 | D22: Morrisville | E22: =COUNTIF(Taxi_Data1!E2:E106,D22) -> 9
B23: Midtown | C23: =COUNTIF(Taxi_Data1!E3:E107,B23) -> 3 | D23: Fort Pierce | E23: =COUNTIF(Taxi_Data1!E3:E107,D23) -> 4
B24: New York | C24: =COUNTIF(Taxi_Data1!E4:E108,B24) -> 2 | D24: West Palm Beach | E24: =COUNTIF(Taxi_Data1!E4:E108,D24) -> 2
B25: Cary | C25: =COUNTIF(Taxi_Data1!E5:E109,B25) -> 27 | D25: Durham | E25: =COUNTIF(Taxi_Data1!E5:E109,D25) -> 4
B26: Morrisville | C26: =COUNTIF(Taxi_Data1!E6:E110,B26) -> 9 | D26: Cary | E26: =COUNTIF(Taxi_Data1!E6:E110,D26) -> 27
B27: Durham | C27: =COUNTIF(Taxi_Data1!E7:E111,B27) -> 4 | D27: Raleigh | E27: =COUNTIF(Taxi_Data1!E7:E111,D27) -> 7
B28: Whitebridge | C28: =COUNTIF(Taxi_Data1!E8:E112,B28) -> 11 | D28: Edgehill Farms | E28: =COUNTIF(Taxi_Data1!E8:E112,D28) -> 2
B31: Q7) Find Count of Rides and its Percenatge on each weekday. Use Pivot Table. Represent it on Pie chart
B33: Day | C33: Count | D33: Count_Percentage
B34: Monday
B35: Tuesday
B36: Wednesday
B37: Thursday
B38: Friday
B39: Saturday
B40: Sunday
B43: Q8) Find top 7 most busiest Drivers. Display Driver Names and Count of their ride
B44: Q9) Find Count of To and Fro Rides i.e. Rides where Start and End Locations are Same
B45: Q10) Find Count of recods where Purpose is null
B46: Q11) Find Count of each Purpose and its percentage. Use Pivot table

Sheet Solutions
B2: Ans1
B3: Solved in Taxi_data1 sheet
B5: Ans2
B6: Avg_Distance | C6: =AVERAGE(Taxi_Data1!G2:G106) -> 7.1609524
B7: Avg_Fare | C7: =AVERAGE(Taxi_Data2!B2:B106) -> 77.104762
B9: Ans3
B11: Peak Hour | C11: Count of Rides
B12: 13 | C12: 12
B13: 16 | C13: 11
B14: 14 | C14: 11
B15: 18 | C15: 9
B16: 15 | C16: 9
B17: Grand Total | C17: 52
B22: Ans7
B38: Ans8 | C38: Busiest Driver
B41: Drivers | C41: Count of Driver
B42: Martin | C42: 10
B43: Shawn | C43: 9
B44: Robin | C44: 8
B45: Ian | C45: 8
B46: David | C46: 8
B47: Jason | C47: 7
B48: Javier | C48: 6
B49: Grand Total | C49: 56
B53: Ans9
B54: =COUNTIF(Taxi_Data1!L2:L106,"To and Fro") -> 15 | C54: =FORMULATEXT(B54) -> =COUNTIF(Taxi_Data1!L2:L106,"To and Fro")
B56: Ans10
B57: =COUNTBLANK(Taxi_Data1!H2:H106) -> 18 | C57: =FORMULATEXT(B57) -> =COUNTBLANK(Taxi_Data1!H2:H106)
B60: Ans11
